Workbook
Name Slicer_diabetes_status: #N/A
Name Slicer_weight_status: #N/A

Sheet Customer Names
A1: Customer ID | B1: name
A2: Id1 | B2: Hawks, Ms. Kelly
A3: Id2 | B3: Lehner, Mr. Matthew D
A4: Id3 | B4: Lu, Mr. Phil
A5: Id4 | B5: Osborne, Ms. Kelsey
A6: Id5 | B6: Kadala, Ms. Kristyn
A7: Id6 | B7: Baker, Mr. Russell B.
A8: Id7 | B8: Macpherson, Mr. Scott
A9: Id8 | B9: Hallman, Mr. Stephen
A10: Id9 | B10: Moran, Mr. Patrick R.
A11: Id10 | B11: Benner, Ms. Brooke N.
A12: Id11 | B12: Fierro Vargas, Ms. Paola Andrea
... A2336: Id2335 | B2336: German, Mr. Aaron K

Sheet Medical Examinations
A1: Customer ID | B1: BMI | C1: HBA1C | D1: Heart Issues | E1: Any Transplants | F1: Cancer history | G1: NumberOfMajorSurgeries | H1: smoker
A2: Id1 | B2: 47.41 | C2: 7.47 | D2: No | E2: No | F2: No | G2: No major surgery | H2: yes
A3: Id2 | B3: 30.36 | C3: 5.77 | D3: No | E3: No | F3: No | G3: No major surgery | H3: yes
A4: Id3 | B4: 34.485 | C4: 11.87 | D4: yes | E4: No | F4: No | G4: 2 | H4: yes
A5: Id4 | B5: 38.095 | C5: 6.05 | D5: No | E5: No | F5: No | G5: No major surgery | H5: yes
A6: Id5 | B6: 35.53 | C6: 5.45 | D6: No | E6: No | F6: No | G6: No major surgery | H6: yes
A7: Id6 | B7: 32.8 | C7: 6.59 | D7: No | E7: No | F7: No | G7: No major surgery | H7: yes
A8: Id7 | B8: 36.4 | C8: 6.07 | D8: No | E8: No | F8: No | G8: No major surgery | H8: yes
A9: Id8 | B9: 36.96 | C9: 7.93 | D9: No | E9: No | F9: No | G9: 3 | H9: yes
A10: Id9 | B10: 41.14 | C10: 9.58 | D10: yes | E10: No | F10: Yes | G10: 1 | H10: yes
A11: Id10 | B11: 38.06 | C11: 10.79 | D11: No | E11: No | F11: No | G11: No major surgery | H11: yes
A12: Id11 | B12: 37.7 | C12: 5.96 | D12: yes | E12: No | F12: No | G12: 2 | H12: yes
A13: Id12 | B13: 42.13 | C13: 11.9 | D13: No | E13: No | F13: No | G13: No major surgery | H13: yes
A14: Id13 | B14: 40.92 | C14: 8.41 | D14: No | E14: No | F14: No | G14: No major surgery | H14: yes
A15: Id14 | B15: 40.565 | C15: 7.02 | D15: No | E15: No | F15: No | G15: No major surgery | H15: yes
A16: Id15 | B16: 36.385 | C16: 7.59 | D16: yes | E16: No | F16: No | G16: 2 | H16: yes
A17: Id16 | B17: 39.9 | C17: 11.32 | D17: No | E17: No | F17: No | G17: No major surgery | H17: yes
A18: Id17 | B18: 33.8 | C18: 7.67 | D18: No | E18: No | F18: No | G18: 3 | H18: yes
A19: Id18 | B19: 36.765 | C19: 7.29 | D19: yes | E19: No | F19: Yes | G19: 1 | H19: yes
A20: Id19 | B20: 36.955 | C20: 4.72 | D20: yes | E20: No | F20: No | G20: 1 | H20: yes
A21: Id20 | B21: 42.9 | C21: 11.41 | D21: No | E21: No | F21: No | G21: No major surgery | H21: yes
A22: Id21 | B22: 36.3 | C22: 11.5 | D22: yes | E22: No | F22: No | G22: 2 | H22: yes
A23: Id22 | B23: 32.2 | C23: 6.22 | D23: yes | E23: No | F23: No | G23: 2 | H23: yes
A24: Id23 | B24: 31.3 | C24: 11.38 | D24: No | E24: No | F24: No | G24: 3 | H24: yes
A25: Id24 | B25: 41.8 | C25: 7.89 | D25: yes | E25: No | F25: No | G25: 2 | H25: yes
A26: Id25 | B26: 35.09 | C26: 4.38 | D26: yes | E26: No | F26: No | G26: 2 | H26: yes
A27: Id26 | B27: 33.88 | C27: 7.01 | D27: No | E27: No | F27: No | G27: 3 | H27: yes
A28: Id27 | B28: 30.875 | C28: 11.88 | D28: No | E28: No | F28: No | G28: No major surgery | H28: yes
A29: Id28 | B29: 36.86 | C29: 5.19 | D29: yes | E29: No | F29: Yes | G29: 1 | H29: yes
A30: Id29 | B30: 35.86 | C30: 6.74 | D30: yes | E30: No | F30: No | G30: 2 | H30: yes
A31: Id30 | B31: 37.05 | C31: 8.44 | D31: No | E31: No | F31: No | G31: No major surgery | H31: yes
A32: Id31 | B32: 43.89 | C32: 8.71 | D32: No | E32: No | F32: No | G32: No major surgery | H32: yes
A33: Id32 | B33: 42.35 | C33: 5.08 | D33: yes | E33: No | F33: No | G33: No major surgery | H33: yes
A34: Id33 | B34: 31.35 | C34: 6.86 | D34: No | E34: No | F34: No | G34: No major surgery | H34: yes
A35: Id34 | B35: 47.6 | C35: 5.95 | D35: yes | E35: No | F35: No | G35: No major surgery | H35: yes
A36: Id35 | B36: 46.2 | C36: 6.09 | D36: No | E36: No | F36: Yes | G36: 1 | H36: yes
A37: Id36 | B37: 32.015 | C37: 11.75 | D37: No | E37: No | F37: No | G37: No major surgery | H37: yes
A38: Id37 | B38: 40.565 | C38: 7.37 | D38: No | E38: No | F38: No | G38: No major surgery | H38: yes
A39: Id38 | B39: 32.45 | C39: 11.91 | D39: No | E39: No | F39: No | G39: No major surgery | H39: yes
A40: Id39 | B40: 34.96 | C40: 6.52 | D40: No | E40: No | F40: No | G40: No major surgery | H40: yes
...

Sheet Sheet3
L1: 4 | M1: Average of charges for each hospital tier within different states
A2: 1.cancer history among smokers and non-smokers | E2: 2 | F2: major surgeries and average HBA1C based on transplants
A3: Count of customer id | B3: Column Labels | F3: any transplants | G3: Average of HBA1C | H3: Sum of NumberOfMajorSurgeries
A4: smoker | B4: no cancer | C4: cancer | D4: Grand Total | F4: No | G4: 6.6704427 | H4: 1417
A5: No | B5: 1540 | C5: 307 | D5: 1847 | F5: Yes | G5: 5.1876389 | H5: 162
A6: Yes | B6: 404 | C6: 84 | D6: 488 | F6: Grand Total | G6: 6.5789979 | H6: 1579
A7: Grand Total | B7: 1944 | C7: 391 | D7: 2335
E19: 4 | F19: Average of charges for each hospital tier within different states
F20: state id | G20: tier - 1 | H20: tier - 2 | I20: tier - 3 | J20: #N/A | K20: Grand Total
F21: R1011 | G21: 34314.781 | H21: 29807.474 | I21: 12506.437 | K21: 27292.219
F22: R1012 | G22: 28715.308 | H22: 21628.8 | I22: 12366.133 | K22: 19094.489
F23: R1013 | G23: 33437.089 | H23: 27210.805 | I23: 12149.212 | K23: 24397.403
F24: R1014 | G24: 33406.407 | I24: 16950.485 | K24: 26824.038
F25: R1015 | G25: 39556.49 | H25: 28882.473 | I25: 10407.09 | K25: 27322.2
F26: R1016 | G26: 39868.616 | H26: 25643.571 | I26: 12201.369 | K26: 22715.816
F27: R1017 | G27: 34070.596 | H27: 22996.254 | I27: 11968.509 | K27: 23013.421
F28: R1018 | G28: 33475.82 | H28: 15864.583 | I28: 12570.97 | K28: 17701.918
F29: R1019 | G29: 27621.61 | H29: 13705.733 | I29: 15407.321 | K29: 18905.239
F30: R1020 | I30: 11716.453 | K30: 11716.453
F31: R1021 | H31: 12926.584 | I31: 11518.786 | K31: 11882.088
F32: R1022 | H32: 14958.005 | I32: 11637.812 | K32: 13113.453
F33: R1023 | G33: 18261.757 | H33: 16088.17 | I33: 12785.637 | K33: 15327.827
F34: R1024 | G34: 32732.187 | H34: 19673.542 | I34: 13360.979 | K34: 19156.9
F35: R1025 | H35: 12252.64 | I35: 11408.371 | K35: 11488.777
F36: R1026 | G36: 18709.798 | H36: 15458.604 | I36: 12296.78 | K36: 13932.369
F37: unknown | G37: 37165.16 | K37: 37165.16
F38: #N/A | J38: #N/A | K38: #N/A
F39: Grand Total | G39: 32449.323 | H39: 24644.638 | I39: 12411.354 | J39: #N/A | K39: #N/A

Sheet Sheet4
A3: Average of charges | B3: Column Labels
A4: Row Labels | B4: NORMAL WEIGHT | C4: OBESITY | D4: OVER WEIGHT | E4: UNDER WEIGHT | F4: Grand Total
A5: DIABETES | B5: #N/A | C5: #N/A | D5: #N/A | E5: #N/A | F5: #N/A
A6: NORMAL | B6: #N/A | C6: #N/A | D6: #N/A | E6: #N/A | F6: #N/A
A7: PREDIABETES | B7: #N/A | C7: #N/A | D7: #N/A | E7: #N/A | F7: #N/A
A8: Grand Total | B8: #N/A | C8: #N/A | D8: #N/A | E8: #N/A | F8: #N/A

Sheet health care
A1: customer id | B1: first name | C1: BMI | D1: HBA1C | E1: Heart Issues | F1: Any Transplants | G1: Cancer history | H1: NumberOfMajorSurgeries | I1: smoker | J1: diabetes status | K1: weight status | L1: charges | M1: Hospital tier | N1: City tier | O1: State ID | P1: Date of birth | Q1: AGE
A2: {=vloo} -> #NAME? | B2: Hawks | C2: =VLOOKUP(A2,table2!A2:J2336,2,FALSE) -> #NAME? | D2: =VLOOKUP(A2,table2!A2:J2336,3,FALSE) -> #NAME? | E2: =VLOOKUP(A2,table2!A2:J2336,4,FALSE) -> #NAME? | F2: =VLOOKUP(A2,table2!A2:J2336,5,FALSE) -> #NAME? | G2: =VLOOKUP(A2,table2!A2:J2336,6,FALSE) -> #NAME? | H2: =VLOOKUP(A2,table2!A2:J2336,7,FALSE) -> #NAME? | I2: =VLOOKUP(A2,table2!A2:J2336,8,FALSE) -> #NAME? | J2: =VLOOKUP(A2,table2!A2:J2336,9,FALSE) -> #NAME? | K2: =VLOOKUP(A2,table2!A2:J2336,10,FALSE) -> #NAME? | L2: ='health care'!L3 -> 571 | M2: =VLOOKUP(A2,table3!A2:H2342,5,FALSE) -> #NAME? | N2: =VLOOKUP(A2,table3!A2:H2342,6,FALSE) -> #NAME? | O2: =VLOOKUP(A2,table3!A2:H2342,7,FALSE) -> #NAME? | P2: =VLOOKUP(A2,table3!A2:H2342,2,FALSE) -> #NAME? | Q2: =VLOOKUP(A2,table3!A1:H2342,8,FALSE) -> #NAME? | S2: =VLOOKUP(A2,table3__3[],3,FALSE) -> #NAME? | T2: =VLOOKUP(A2,table3__3[],4,) -> #NAME?
A3: Id2 | B3: Lehner | C3: =VLOOKUP(A3,table2!A3:J2337,2,FALSE) -> 30.36 | D3: =VLOOKUP(A3,table2!A3:J2337,3,FALSE) -> 5.77 | E3: =VLOOKUP(A3,table2!A3:J2337,4,FALSE) -> No | F3: =VLOOKUP(A3,table2!A3:J2337,5,FALSE) -> No | G3: =VLOOKUP(A3,table2!A3:J2337,6,FALSE) -> No | H3: =VLOOKUP(A3,table2!A3:J2337,7,FALSE) -> 0 | I3: =VLOOKUP(A3,table2!A3:J2337,8,FALSE) -> Yes | J3: =VLOOKUP(A3,table2!A3:J2337,9,FALSE) -> OBESITY | K3: =VLOOKUP(A3,table2!A3:J2337,10,FALSE) -> PREDIABETES | L3: =VLOOKUP(A3,table3!A3:H2343,4,FALSE) -> 571 | M3: =VLOOKUP(A3,table3!A3:H2343,5,FALSE) -> tier - 2 | N3: =VLOOKUP(A3,table3!A3:H2343,6,FALSE) -> tier - 1 | O3: =VLOOKUP(A3,table3!A3:H2343,7,FALSE) -> R1013 | P3: =VLOOKUP(A3,table3!A3:H2343,2,FALSE) -> 33938 | Q3: =VLOOKUP(A3,table3!A2:H2343,8,FALSE) -> 30
A4: Id3 | B4: Lu | C4: =VLOOKUP(A4,table2!A4:J2338,2,FALSE) -> 34.485 | D4: =VLOOKUP(A4,table2!A4:J2338,3,FALSE) -> 11.87 | E4: =VLOOKUP(A4,table2!A4:J2338,4,FALSE) -> Yes | F4: =VLOOKUP(A4,table2!A4:J2338,5,FALSE) -> No | G4: =VLOOKUP(A4,table2!A4:J2338,6,FALSE) -> No | H4: =VLOOKUP(A4,table2!A4:J2338,7,FALSE) -> 2 | I4: =VLOOKUP(A4,table2!A4:J2338,8,FALSE) -> Yes | J4: =VLOOKUP(A4,table2!A4:J2338,9,FALSE) -> OBESITY | K4: =VLOOKUP(A4,table2!A4:J2338,10,FALSE) -> DIABETES | L4: =VLOOKUP(A4,table3!A4:H2344,4,FALSE) -> 600 | M4: =VLOOKUP(A4,table3!A4:H2344,5,FALSE) -> tier - 2 | N4: =VLOOKUP(A4,table3!A4:H2344,6,FALSE) -> tier - 1 | O4: =VLOOKUP(A4,table3!A4:H2344,7,FALSE) -> R1013 | P4: =VLOOKUP(A4,table3!A4:H2344,2,FALSE) -> 34150 | Q4: =VLOOKUP(A4,table3!A3:H2344,8,FALSE) -> 29
A5: Id4 | B5: Osborne | C5: =VLOOKUP(A5,table2!A5:J2339,2,FALSE) -> 38.095 | D5: =VLOOKUP(A5,table2!A5:J2339,3,FALSE) -> 6.05 | E5: =VLOOKUP(A5,table2!A5:J2339,4,FALSE) -> No | F5: =VLOOKUP(A5,table2!A5:J2339,5,FALSE) -> No | G5: =VLOOKUP(A5,table2!A5:J2339,6,FALSE) -> No | H5: =VLOOKUP(A5,table2!A5:J2339,7,FALSE) -> 0 | I5: =VLOOKUP(A5,table2!A5:J2339,8,FALSE) -> Yes | J5: =VLOOKUP(A5,table2!A5:J2339,9,FALSE) -> OBESITY | K5: =VLOOKUP(A5,table2!A5:J2339,10,FALSE) -> PREDIABETES | L5: =VLOOKUP(A5,table3!A5:H2345,4,FALSE) -> 605 | M5: =VLOOKUP(A5,table3!A5:H2345,5,FALSE) -> tier - 3 | N5: =VLOOKUP(A5,table3!A5:H2345,6,FALSE) -> tier - 3 | O5: =VLOOKUP(A5,table3!A5:H2345,7,FALSE) -> R1013 | P5: =VLOOKUP(A5,table3!A5:H2345,2,FALSE) -> 33860 | Q5: =VLOOKUP(A5,table3!A4:H2345,8,FALSE) -> 30
A6: Id5 | B6: Kadala | C6: =VLOOKUP(A6,table2!A6:J2340,2,FALSE) -> 35.53 | D6: =VLOOKUP(A6,table2!A6:J2340,3,FALSE) -> 5.45 | E6: =VLOOKUP(A6,table2!A6:J2340,4,FALSE) -> No | F6: =VLOOKUP(A6,table2!A6:J2340,5,FALSE) -> No | G6: =VLOOKUP(A6,table2!A6:J2340,6,FALSE) -> No | H6: =VLOOKUP(A6,table2!A6:J2340,7,FALSE) -> 0 | I6: =VLOOKUP(A6,table2!A6:J2340,8,FALSE) -> Yes | J6: =VLOOKUP(A6,table2!A6:J2340,9,FALSE) -> OBESITY | K6: =VLOOKUP(A6,table2!A6:J2340,10,FALSE) -> NORMAL | L6: =VLOOKUP(A6,table3!A6:H2346,4,FALSE) -> 637 | M6: =VLOOKUP(A6,table3!A6:H2346,5,FALSE) -> tier - 3 | N6: =VLOOKUP(A6,table3!A6:H2346,6,FALSE) -> tier - 3 | O6: =VLOOKUP(A6,table3!A6:H2346,7,FALSE) -> R1013 | P6: =VLOOKUP(A6,table3!A6:H2346,2,FALSE) -> 36003 | Q6: =VLOOKUP(A6,table3!A5:H2346,8,FALSE) -> 24
A7: Id6 | B7: Baker | C7: =VLOOKUP(A7,table2!A7:J2341,2,FALSE) -> 32.8 | D7: =VLOOKUP(A7,table2!A7:J2341,3,FALSE) -> 6.59 | E7: =VLOOKUP(A7,table2!A7:J2341,4,FALSE) -> No | F7: =VLOOKUP(A7,table2!A7:J2341,5,FALSE) -> No | G7: =VLOOKUP(A7,table2!A7:J2341,6,FALSE) -> No | H7: =VLOOKUP(A7,table2!A7:J2341,7,FALSE) -> 0 | I7: =VLOOKUP(A7,table2!A7:J2341,8,FALSE) -> Yes | J7: =VLOOKUP(A7,table2!A7:J2341,9,FALSE) -> OBESITY | K7: =VLOOKUP(A7,table2!A7:J2341,10,FALSE) -> DIABETES | L7: =VLOOKUP(A7,table3!A7:H2347,4,FALSE) -> 646 | M7: =VLOOKUP(A7,table3!A7:H2347,5,FALSE) -> tier - 3 | N7: =VLOOKUP(A7,table3!A7:H2347,6,FALSE) -> tier - 3 | O7: =VLOOKUP(A7,table3!A7:H2347,7,FALSE) -> R1012 | P7: =VLOOKUP(A7,table3!A7:H2347,2,FALSE) -> 37215 | Q7: =VLOOKUP(A7,table3!A6:H2347,8,FALSE) -> 21
A8: Id7 | B8: Macpherson | C8: =VLOOKUP(A8,table2!A8:J2342,2,FALSE) -> 36.4 | D8: =VLOOKUP(A8,table2!A8:J2342,3,FALSE) -> 6.07 | E8: =VLOOKUP(A8,table2!A8:J2342,4,FALSE) -> No | F8: =VLOOKUP(A8,table2!A8:J2342,5,FALSE) -> No | G8: =VLOOKUP(A8,table2!A8:J2342,6,FALSE) -> No | H8: =VLOOKUP(A8,table2!A8:J2342,7,FALSE) -> 0 | I8: =VLOOKUP(A8,table2!A8:J2342,8,FALSE) -> Yes | J8: =VLOOKUP(A8,table2!A8:J2342,9,FALSE) -> OBESITY | K8: =VLOOKUP(A8,table2!A8:J2342,10,FALSE) -> PREDIABETES | L8: =VLOOKUP(A8,table3!A8:H2348,4,FALSE) -> 650 | M8: =VLOOKUP(A8,table3!A8:H2348,5,FALSE) -> tier - 3 | N8: =VLOOKUP(A8,table3!A8:H2348,6,FALSE) -> tier - 3 | O8: =VLOOKUP(A8,table3!A8:H2348,7,FALSE) -> R1013 | P8: =VLOOKUP(A8,table3!A8:H2348,2,FALSE) -> 34121 | Q8: =VLOOKUP(A8,table3!A7:H2348,8,FALSE) -> 30
A9: Id8 | B9: Hallman | C9: =VLOOKUP(A9,table2!A9:J2343,2,FALSE) -> 36.96 | D9: =VLOOKUP(A9,table2!A9:J2343,3,FALSE) -> 7.93 | E9: =VLOOKUP(A9,table2!A9:J2343,4,FALSE) -> No | F9: =VLOOKUP(A9,table2!A9:J2343,5,FALSE) -> No | G9: =VLOOKUP(A9,table2!A9:J2343,6,FALSE) -> No | H9: =VLOOKUP(A9,table2!A9:J2343,7,FALSE) -> 3 | I9: =VLOOKUP(A9,table2!A9:J2343,8,FALSE) -> Yes | J9: =VLOOKUP(A9,table2!A9:J2343,9,FALSE) -> OBESITY | K9: =VLOOKUP(A9,table2!A9:J2343,10,FALSE) -> DIABETES | L9: =VLOOKUP(A9,table3!A9:H2349,4,FALSE) -> 650 | M9: =VLOOKUP(A9,table3!A9:H2349,5,FALSE) -> tier - 3 | N9: =VLOOKUP(A9,table3!A9:H2349,6,FALSE) -> tier - 3 | O9: =VLOOKUP(A9,table3!A9:H2349,7,FALSE) -> R1013 | P9: =VLOOKUP(A9,table3!A9:H2349,2,FALSE) -> 34884 | Q9: =VLOOKUP(A9,table3!A8:H2349,8,FALSE) -> 27
A10: Id9 | B10: Moran | C10: =VLOOKUP(A10,table2!A10:J2344,2,FALSE) -> 41.14 | D10: =VLOOKUP(A10,table2!A10:J2344,3,FALSE) -> 9.58 | E10: =VLOOKUP(A10,table2!A10:J2344,4,FALSE) -> Yes | F10: =VLOOKUP(A10,table2!A10:J2344,5,FALSE) -> No | G10: =VLOOKUP(A10,table2!A10:J2344,6,FALSE) -> Yes | H10: =VLOOKUP(A10,table2!A10:J2344,7,FALSE) -> 1 | I10: =VLOOKUP(A10,table2!A10:J2344,8,FALSE) -> Yes | J10: =VLOOKUP(A10,table2!A10:J2344,9,FALSE) -> OBESITY | K10: =VLOOKUP(A10,table2!A10:J2344,10,FALSE) -> DIABETES | L10: =VLOOKUP(A10,table3!A10:H2350,4,FALSE) -> 668 | M10: =VLOOKUP(A10,table3!A10:H2350,5,FALSE) -> tier - 3 | N10: =VLOOKUP(A10,table3!A10:H2350,6,FALSE) -> tier - 2 | O10: =VLOOKUP(A10,table3!A10:H2350,7,FALSE) -> R1012 | P10: =VLOOKUP(A10,table3!A10:H2350,2,FALSE) -> 37589 | Q10: =VLOOKUP(A10,table3!A9:H2350,8,FALSE) -> 20
A11: Id10 | B11: Benner | C11: =VLOOKUP(A11,table2!A11:J2345,2,FALSE) -> 38.06 | D11: =VLOOKUP(A11,table2!A11:J2345,3,FALSE) -> 10.79 | E11: =VLOOKUP(A11,table2!A11:J2345,4,FALSE) -> No | F11: =VLOOKUP(A11,table2!A11:J2345,5,FALSE) -> No | G11: =VLOOKUP(A11,table2!A11:J2345,6,FALSE) -> No | H11: =VLOOKUP(A11,table2!A11:J2345,7,FALSE) -> 0 | I11: =VLOOKUP(A11,table2!A11:J2345,8,FALSE) -> Yes | J11: =VLOOKUP(A11,table2!A11:J2345,9,FALSE) -> OBESITY | K11: =VLOOKUP(A11,table2!A11:J2345,10,FALSE) -> DIABETES | L11: =VLOOKUP(A11,table3!A11:H2351,4,FALSE) -> 670 | M11: =VLOOKUP(A11,table3!A11:H2351,5,FALSE) -> tier - 3 | N11: =VLOOKUP(A11,table3!A11:H2351,6,FALSE) -> tier - 3 | O11: =VLOOKUP(A11,table3!A11:H2351,7,FALSE) -> R1013 | P11: =VLOOKUP(A11,table3!A11:H2351,2,FALSE) -> 35743 | Q11: =VLOOKUP(A11,table3!A10:H2351,8,FALSE) -> 25
A12: Id11 | B12: Fierro Vargas | C12: =VLOOKUP(A12,table2!A12:J2346,2,FALSE) -> 37.7 | D12: =VLOOKUP(A12,table2!A12:J2346,3,FALSE) -> 5.96 | E12: =VLOOKUP(A12,table2!A12:J2346,4,FALSE) -> Yes | F12: =VLOOKUP(A12,table2!A12:J2346,5,FALSE) -> No | G12: =VLOOKUP(A12,table2!A12:J2346,6,FALSE) -> No | H12: =VLOOKUP(A12,table2!A12:J2346,7,FALSE) -> 2 | I12: =VLOOKUP(A12,table2!A12:J2346,8,FALSE) -> Yes | J12: =VLOOKUP(A12,table2!A12:J2346,9,FALSE) -> OBESITY | K12: =VLOOKUP(A12,table2!A12:J2346,10,FALSE) -> PREDIABETES | L12: =VLOOKUP(A12,table3!A12:H2352,4,FALSE) -> 688 | M12: =VLOOKUP(A12,table3!A12:H2352,5,FALSE) -> tier - 3 | N12: =VLOOKUP(A12,table3!A12:H2352,6,FALSE) -> tier - 2 | O12: =VLOOKUP(A12,table3!A12:H2352,7,FALSE) -> R1013 | P12: =VLOOKUP(A12,table3!A12:H2352,2,FALSE) -> 37146 | Q12: =VLOOKUP(A12,table3!A11:H2352,8,FALSE) -> 21
A13: Id12 | B13: Franz | C13: =VLOOKUP(A13,table2!A13:J2347,2,FALSE) -> 42.13 | D13: =VLOOKUP(A13,table2!A13:J2347,3,FALSE) -> 11.9 | E13: =VLOOKUP(A13,table2!A13:J2347,4,FALSE) -> No | F13: =VLOOKUP(A13,table2!A13:J2347,5,FALSE) -> No | G13: =VLOOKUP(A13,table2!A13:J2347,6,FALSE) -> No | H13: =VLOOKUP(A13,table2!A13:J2347,7,FALSE) -> 0 | I13: =VLOOKUP(A13,table2!A13:J2347,8,FALSE) -> Yes | J13: =VLOOKUP(A13,table2!A13:J2347,9,FALSE) -> OBESITY | K13: =VLOOKUP(A13,table2!A13:J2347,10,FALSE) -> DIABETES | L13: =VLOOKUP(A13,table3!A13:H2353,4,FALSE) -> 700 | M13: =VLOOKUP(A13,table3!A13:H2353,5,FALSE) -> tier - 2 | N13: =VLOOKUP(A13,table3!A13:H2353,6,FALSE) -> tier - 3 | O13: =VLOOKUP(A13,table3!A13:H2353,7,FALSE) -> R1013 | P13: =VLOOKUP(A13,table3!A13:H2353,2,FALSE) -> 36520 | Q13: =VLOOKUP(A13,table3!A12:H2353,8,FALSE) -> 23
A14: Id13 | B14: Foster | C14: =VLOOKUP(A14,table2!A14:J2348,2,FALSE) -> 40.92 | D14: =VLOOKUP(A14,table2!A14:J2348,3,FALSE) -> 8.41 | E14: =VLOOKUP(A14,table2!A14:J2348,4,FALSE) -> No | F14: =VLOOKUP(A14,table2!A14:J2348,5,FALSE) -> No | G14: =VLOOKUP(A14,table2!A14:J2348,6,FALSE) -> No | H14: =VLOOKUP(A14,table2!A14:J2348,7,FALSE) -> 0 | I14: =VLOOKUP(A14,table2!A14:J2348,8,FALSE) -> Yes | J14: =VLOOKUP(A14,table2!A14:J2348,9,FALSE) -> OBESITY | K14: =VLOOKUP(A14,table2!A14:J2348,10,FALSE) -> DIABETES | L14: =VLOOKUP(A14,table3!A14:H2354,4,FALSE) -> 723 | M14: =VLOOKUP(A14,table3!A14:H2354,5,FALSE) -> tier - 3 | N14: =VLOOKUP(A14,table3!A14:H2354,6,FALSE) -> tier - 1 | O14: =VLOOKUP(A14,table3!A14:H2354,7,FALSE) -> R1013 | P14: =VLOOKUP(A14,table3!A14:H2354,2,FALSE) -> 36508 | Q14: =VLOOKUP(A14,table3!A13:H2354,8,FALSE) -> 23
... A1169: Id1168 | B1169: Giumarra | C1169: =VLOOKUP(A1169,table2!A1169:J3503,2,FALSE) -> 25.75 | D1169: =VLOOKUP(A1169,table2!A1169:J3503,3,FALSE) -> 9.23 | E1169: =VLOOKUP(A1169,table2!A1169:J3503,4,FALSE) -> No | F1169: =VLOOKUP(A1169,table2!A1169:J3503,5,FALSE) -> No | G1169: =VLOOKUP(A1169,table2!A1169:J3503,6,FALSE) -> No | H1169: =VLOOKUP(A1169,table2!A1169:J3503,7,FALSE) -> 0 | I1169: =VLOOKUP(A1169,table2!A1169:J3503,8,FALSE) -> No | J1169: =VLOOKUP(A1169,table2!A1169:J3503,9,FALSE) -> OVER WEIGHT | K1169: =VLOOKUP(A1169,table2!A1169:J3503,10,FALSE) -> DIABETES | L1169: =VLOOKUP(A1169,table3!A1169:H3509,4,FALSE) -> 9630 | M1169: =VLOOKUP(A1169,table3!A1169:H3509,5,FALSE) -> tier - 2 | N1169: =VLOOKUP(A1169,table3!A1169:H3509,6,FALSE) -> tier - 2 | O1169: =VLOOKUP(A1169,table3!A1169:H3509,7,FALSE) -> R1011 | P1169: =VLOOKUP(A1169,table3!A1169:H3509,2,FALSE) -> 26595 | Q1169: =VLOOKUP(A1169,table3!A1168:H3509,8,FALSE) -> 50
A1170: Id1169 | B1170: Peters | C1170: =VLOOKUP(A1170,table2!A1170:J3504,2,FALSE) -> 32.3 | D1170: =VLOOKUP(A1170,table2!A1170:J3504,3,FALSE) -> 4.37 | E1170: =VLOOKUP(A1170,table2!A1170:J3504,4,FALSE) -> No | F1170: =VLOOKUP(A1170,table2!A1170:J3504,5,FALSE) -> No | G1170: =VLOOKUP(A1170,table2!A1170:J3504,6,FALSE) -> No | H1170: =VLOOKUP(A1170,table2!A1170:J3504,7,FALSE) -> 2 | I1170: =VLOOKUP(A1170,table2!A1170:J3504,8,FALSE) -> No | J1170: =VLOOKUP(A1170,table2!A1170:J3504,9,FALSE) -> OBESITY | K1170: =VLOOKUP(A1170,table2!A1170:J3504,10,FALSE) -> NORMAL | L1170: =VLOOKUP(A1170,table3__3[],4,FALSE) -> 9631 | M1170: =VLOOKUP(A1170,table3__3[],5,FALSE) -> tier - 3 | N1170: =VLOOKUP(A1170,table3__3[],6,) -> tier - 2 | O1170: =VLOOKUP(A1170,table3__3[],7,FALSE) -> R1013 | P1170: =VLOOKUP(A1170,table3__3[],8,FALSE) -> 54 | Q1170: =VLOOKUP(A1170,table3!A1169:H3510,8,FALSE) -> 54
A1171: Id1170 | B1171: Bower | C1171: =VLOOKUP(A1171,table2!A1171:J3505,2,FALSE) -> 28.61 | D1171: =VLOOKUP(A1171,table2!A1171:J3505,3,FALSE) -> 5.76 | E1171: =VLOOKUP(A1171,table2!A1171:J3505,4,FALSE) -> No | F1171: =VLOOKUP(A1171,table2!A1171:J3505,5,FALSE) -> No | G1171: =VLOOKUP(A1171,table2!A1171:J3505,6,FALSE) -> Yes | H1171: =VLOOKUP(A1171,table2!A1171:J3505,7,FALSE) -> 1 | I1171: =VLOOKUP(A1171,table2!A1171:J3505,8,FALSE) -> No | J1171: =VLOOKUP(A1171,table2!A1171:J3505,9,FALSE) -> OVER WEIGHT | K1171: =VLOOKUP(A1171,table2!A1171:J3505,10,FALSE) -> PREDIABETES | L1171: =VLOOKUP(A1171,table3__3[],4,FALSE) -> 9635 | M1171: =VLOOKUP(A1171,table3__3[],5,FALSE) -> tier - 2 | N1171: =VLOOKUP(A1171,table3__3[],6,) -> tier - 2 | O1171: =VLOOKUP(A1171,table3__3[],7,FALSE) -> R1011 | P1171: =VLOOKUP(A1171,table3__3[],8,FALSE) -> 52 | Q1171: =VLOOKUP(A1170,table3__3[],8,) -> 54
A1172: Id1171 | B1172: Chen | C1172: =VLOOKUP(A1172,table2!A1172:J3506,2,FALSE) -> 45.41 | D1172: =VLOOKUP(A1172,table2!A1172:J3506,3,FALSE) -> 4.96 | E1172: =VLOOKUP(A1172,table2!A1172:J3506,4,FALSE) -> No | F1172: =VLOOKUP(A1172,table2!A1172:J3506,5,FALSE) -> No | G1172: =VLOOKUP(A1172,table2!A1172:J3506,6,FALSE) -> No | H1172: =VLOOKUP(A1172,table2!A1172:J3506,7,FALSE) -> 1 | I1172: =VLOOKUP(A1172,table2!A1172:J3506,8,FALSE) -> No | J1172: =VLOOKUP(A1172,table2!A1172:J3506,9,FALSE) -> OBESITY | K1172: =VLOOKUP(A1172,table2!A1172:J3506,10,FALSE) -> NORMAL | L1172: =VLOOKUP(A1172,table3__3[],4,FALSE) -> 9644 | M1172: =VLOOKUP(A1172,table3__3[],5,FALSE) -> tier - 2 | N1172: =VLOOKUP(A1172,table3__3[],6,) -> tier - 1 | O1172: =VLOOKUP(A1172,table3__3[],7,FALSE) -> R1012 | P1172: =VLOOKUP(A1172,table3__3[],8,FALSE) -> 51 | Q1172: =VLOOKUP(A1171,table3__3[],8,) -> 52
A1173: Id1172 | B1173: Capriccioso | C1173: =VLOOKUP(A1173,table2!A1173:J3507,2,FALSE) -> 31.2 | D1173: =VLOOKUP(A1173,table2!A1173:J3507,3,FALSE) -> 11.04 | E1173: =VLOOKUP(A1173,table2!A1173:J3507,4,FALSE) -> Yes | F1173: =VLOOKUP(A1173,table2!A1173:J3507,5,FALSE) -> No | G1173: =VLOOKUP(A1173,table2!A1173:J3507,6,FALSE) -> No | H1173: =VLOOKUP(A1173,table2!A1173:J3507,7,FALSE) -> 2 | I1173: =VLOOKUP(A1173,table2!A1173:J3507,8,FALSE) -> No | J1173: =VLOOKUP(A1173,table2!A1173:J3507,9,FALSE) -> OBESITY | K1173: =VLOOKUP(A1173,table2!A1173:J3507,10,FALSE) -> DIABETES | L1173: =VLOOKUP(A1173,table3__3[],4,FALSE) -> 9654 | M1173: =VLOOKUP(A1173,table3__3[],5,FALSE) -> tier - 2 | N1173: =VLOOKUP(A1173,table3__3[],6,) -> tier - 2 | O1173: =VLOOKUP(A1173,table3__3[],7,FALSE) -> R1011 | P1173: =VLOOKUP(A1173,table3__3[],8,FALSE) -> 48 | Q1173: =VLOOKUP(A1172,table3__3[],8,) -> 51
A1174: Id1173 | B1174: Starbuck | C1174: =VLOOKUP(A1174,table2!A1174:J3508,2,FALSE) -> 29.83 | D1174: =VLOOKUP(A1174,table2!A1174:J3508,3,FALSE) -> 7.81 | E1174: =VLOOKUP(A1174,table2!A1174:J3508,4,FALSE) -> Yes | F1174: =VLOOKUP(A1174,table2!A1174:J3508,5,FALSE) -> No | G1174: =VLOOKUP(A1174,table2!A1174:J3508,6,FALSE) -> No | H1174: =VLOOKUP(A1174,table2!A1174:J3508,7,FALSE) -> 1 | I1174: =VLOOKUP(A1174,table2!A1174:J3508,8,FALSE) -> No | J1174: =VLOOKUP(A1174,table2!A1174:J3508,9,FALSE) -> OVER WEIGHT | K1174: =VLOOKUP(A1174,table2!A1174:J3508,10,FALSE) -> DIABETES | L1174: =VLOOKUP(A1174,table3__3[],4,FALSE) -> 9664 | M1174: =VLOOKUP(A1174,table3__3[],5,FALSE) -> tier - 2 | N1174: =VLOOKUP(A1174,table3__3[],6,) -> tier - 3 | O1174: =VLOOKUP(A1174,table3__3[],7,FALSE) -> R1011 | P1174: =VLOOKUP(A1174,table3__3[],8,FALSE) -> 41 | Q1174: =VLOOKUP(A1173,table3__3[],8,) -> 48
A1175: Id1174 | B1175: McMahon | C1175: =VLOOKUP(A1175,table2!A1175:J3509,2,FALSE) -> 29.06 | D1175: =VLOOKUP(A1175,table2!A1175:J3509,3,FALSE) -> 4.55 | E1175: =VLOOKUP(A1175,table2!A1175:J3509,4,FALSE) -> No | F1175: =VLOOKUP(A1175,table2!A1175:J3509,5,FALSE) -> No | G1175: =VLOOKUP(A1175,table2!A1175:J3509,6,FALSE) -> No | H1175: =VLOOKUP(A1175,table2!A1175:J3509,7,FALSE) -> 0 | I1175: =VLOOKUP(A1175,table2!A1175:J3509,8,FALSE) -> No | J1175: =VLOOKUP(A1175,table2!A1175:J3509,9,FALSE) -> OVER WEIGHT | K1175: =VLOOKUP(A1175,table2!A1175:J3509,10,FALSE) -> NORMAL | L1175: =VLOOKUP(A1175,table3__3[],4,FALSE) -> 9684 | M1175: =VLOOKUP(A1175,table3__3[],5,FALSE) -> tier - 3 | N1175: =VLOOKUP(A1175,table3__3[],6,) -> tier - 2 | O1175: =VLOOKUP(A1175,table3__3[],7,FALSE) -> R1013 | P1175: =VLOOKUP(A1175,table3__3[],8,FALSE) -> 56 | Q1175: =VLOOKUP(A1174,table3__3[],8,) -> 41
A1176: Id1175 | B1176: Rissell | C1176: =VLOOKUP(A1176,table2!A1176:J3510,2,FALSE) -> 27.455 | D1176: =VLOOKUP(A1176,table2!A1176:J3510,3,FALSE) -> 6.13 | E1176: =VLOOKUP(A1176,table2!A1176:J3510,4,FALSE) -> No | F1176: =VLOOKUP(A1176,table2!A1176:J3510,5,FALSE) -> No | G1176: =VLOOKUP(A1176,table2!A1176:J3510,6,FALSE) -> No | H1176: =VLOOKUP(A1176,table2!A1176:J3510,7,FALSE) -> 2 | I1176: =VLOOKUP(A1176,table2!A1176:J3510,8,FALSE) -> No | J1176: =VLOOKUP(A1176,table2!A1176:J3510,9,FALSE) -> OVER WEIGHT | K1176: =VLOOKUP(A1176,table2!A1176:J3510,10,FALSE) -> PREDIABETES | L1176: =VLOOKUP(A1176,table3__3[],4,FALSE) -> 9698 | M1176: =VLOOKUP(A1176,table3__3[],5,FALSE) -> tier - 3 | N1176: =VLOOKUP(A1176,table3__3[],6,) -> tier - 3 | O1176: =VLOOKUP(A1176,table3__3[],7,FALSE) -> R1013 | P1176: =VLOOKUP(A1176,table3__3[],8,FALSE) -> 58 | Q1176: =VLOOKUP(A1175,table3__3[],8,) -> 56
A1177: Id1176 | B1177: Kromroy | C1177: =VLOOKUP(A1177,table2!A1177:J3511,2,FALSE) -> 23.01 | D1177: =VLOOKUP(A1177,table2!A1177:J3511,3,FALSE) -> 6.04 | E1177: =VLOOKUP(A1177,table2!A1177:J3511,4,FALSE) -> Yes | F1177: =VLOOKUP(A1177,table2!A1177:J3511,5,FALSE) -> No | G1177: =VLOOKUP(A1177,table2!A1177:J3511,6,FALSE) -> No | H1177: =VLOOKUP(A1177,table2!A1177:J3511,7,FALSE) -> 1 | I1177: =VLOOKUP(A1177,table2!A1177:J3511,8,FALSE) -> No | J1177: =VLOOKUP(A1177,table2!A1177:J3511,9,FALSE) -> NORMAL WEIGHT | K1177: =VLOOKUP(A1177,table2!A1177:J3511,10,FALSE) -> PREDIABETES | L1177: =VLOOKUP(A1177,table3__3[],4,FALSE) -> 9705 | M1177: =VLOOKUP(A1177,table3__3[],5,FALSE) -> tier - 2 | N1177: =VLOOKUP(A1177,table3__3[],6,) -> tier - 3 | O1177: =VLOOKUP(A1177,table3__3[],7,FALSE) -> R1024 | P1177: =VLOOKUP(A1177,table3__3[],8,FALSE) -> 45 | Q1177: =VLOOKUP(A1176,table3__3[],8,) -> 58
A1178: Id1177 | B1178: Manfredi | C1178: =VLOOKUP(A1178,table2!A1178:J3512,2,FALSE) -> 31.39 | D1178: =VLOOKUP(A1178,table2!A1178:J3512,3,FALSE) -> 8.85 | E1178: =VLOOKUP(A1178,table2!A1178:J3512,4,FALSE) -> Yes | F1178: =VLOOKUP(A1178,table2!A1178:J3512,5,FALSE) -> No | G1178: =VLOOKUP(A1178,table2!A1178:J3512,6,FALSE) -> No | H1178: =VLOOKUP(A1178,table2!A1178:J3512,7,FALSE) -> 0 | I1178: =VLOOKUP(A1178,table2!A1178:J3512,8,FALSE) -> No | J1178: =VLOOKUP(A1178,table2!A1178:J3512,9,FALSE) -> OBESITY | K1178: =VLOOKUP(A1178,table2!A1178:J3512,10,FALSE) -> DIABETES | L1178: =VLOOKUP(A1178,table3__3[],4,FALSE) -> 9711 | M1178: =VLOOKUP(A1178,table3__3[],5,FALSE) -> tier - 2 | N1178: =VLOOKUP(A1178,table3__3[],6,) -> tier - 1 | O1178: =VLOOKUP(A1178,table3__3[],7,FALSE) -> R1021 | P1178: =VLOOKUP(A1178,table3__3[],8,FALSE) -> 50 | Q1178: =VLOOKUP(A1177,table3__3[],8,) -> 45
A1179: Id1178 | B1179: Manwaring | C1179: =VLOOKUP(A1179,table2!A1179:J3513,2,FALSE) -> 34.77 | D1179: =VLOOKUP(A1179,table2!A1179:J3513,3,FALSE) -> 10.54 | E1179: =VLOOKUP(A1179,table2!A1179:J3513,4,FALSE) -> No | F1179: =VLOOKUP(A1179,table2!A1179:J3513,5,FALSE) -> No | G1179: =VLOOKUP(A1179,table2!A1179:J3513,6,FALSE) -> No | H1179: =VLOOKUP(A1179,table2!A1179:J3513,7,FALSE) -> 2 | I1179: =VLOOKUP(A1179,table2!A1179:J3513,8,FALSE) -> No | J1179: =VLOOKUP(A1179,table2!A1179:J3513,9,FALSE) -> OBESITY | K1179: =VLOOKUP(A1179,table2!A1179:J3513,10,FALSE) -> DIABETES | L1179: =VLOOKUP(A1179,table3__3[],4,FALSE) -> 9716 | M1179: =VLOOKUP(A1179,table3__3[],5,FALSE) -> tier - 2 | N1179: =VLOOKUP(A1179,table3__3[],6,) -> tier - 1 | O1179: =VLOOKUP(A1179,table3__3[],7,FALSE) -> R1024 | P1179: =VLOOKUP(A1179,table3__3[],8,FALSE) -> 47 | Q1179: =VLOOKUP(A1178,table3__3[],8,) -> 50
A1180: Id1179 | B1180: Tomaszewski | C1180: =VLOOKUP(A1180,table2!A1180:J3514,2,FALSE) -> 24.48 | D1180: =VLOOKUP(A1180,table2!A1180:J3514,3,FALSE) -> 4.37 | E1180: =VLOOKUP(A1180,table2!A1180:J3514,4,FALSE) -> Yes | F1180: =VLOOKUP(A1180,table2!A1180:J3514,5,FALSE) -> No | G1180: =VLOOKUP(A1180,table2!A1180:J3514,6,FALSE) -> No | H1180: =VLOOKUP(A1180,table2!A1180:J3514,7,FALSE) -> 2 | I1180: =VLOOKUP(A1180,table2!A1180:J3514,8,FALSE) -> No | J1180: =VLOOKUP(A1180,table2!A1180:J3514,9,FALSE) -> NORMAL WEIGHT | K1180: =VLOOKUP(A1180,table2!A1180:J3514,10,FALSE) -> NORMAL | L1180: =VLOOKUP(A1180,table3__3[],4,FALSE) -> 9723 | M1180: =VLOOKUP(A1180,table3__3[],5,FALSE) -> tier - 3 | N1180: =VLOOKUP(A1180,table3__3[],6,) -> tier - 1 | O1180: =VLOOKUP(A1180,table3__3[],7,FALSE) -> R1016 | P1180: =VLOOKUP(A1180,table3__3[],8,FALSE) -> 52 | Q1180: =VLOOKUP(A1179,table3__3[],8,) -> 47
A1181: Id1180 | B1181: Gannon | C1181: =VLOOKUP(A1181,table2!A1181:J3515,2,FALSE) -> 22.61 | D1181: =VLOOKUP(A1181,table2!A1181:J3515,3,FALSE) -> 9.63 | E1181: =VLOOKUP(A1181,table2!A1181:J3515,4,FALSE) -> No | F1181: =VLOOKUP(A1181,table2!A1181:J3515,5,FALSE) -> No | G1181: =VLOOKUP(A1181,table2!A1181:J3515,6,FALSE) -> No | H1181: =VLOOKUP(A1181,table2!A1181:J3515,7,FALSE) -> 2 | I1181: =VLOOKUP(A1181,table2!A1181:J3515,8,FALSE) -> No | J1181: =VLOOKUP(A1181,table2!A1181:J3515,9,FALSE) -> NORMAL WEIGHT | K1181: =VLOOKUP(A1181,table2!A1181:J3515,10,FALSE) -> DIABETES | L1181: =VLOOKUP(A1181,table3__3[],4,FALSE) -> 9725 | M1181: =VLOOKUP(A1181,table3__3[],5,FALSE) -> tier - 3 | N1181: =VLOOKUP(A1181,table3__3[],6,) -> tier - 1 | O1181: =VLOOKUP(A1181,table3__3[],7,FALSE) -> R1011 | P1181: =VLOOKUP(A1181,table3__3[],8,FALSE) -> 52 | Q1181: =VLOOKUP(A1180,table3__3[],8,) -> 52
A1182: Id1181 | B1182: Frye | C1182: =VLOOKUP(A1182,table2!A1182:J3516,2,FALSE) -> 34.3 | D1182: =VLOOKUP(A1182,table2!A1182:J3516,3,FALSE) -> 10.37 | E1182: =VLOOKUP(A1182,table2!A1182:J3516,4,FALSE) -> No | F1182: =VLOOKUP(A1182,table2!A1182:J3516,5,FALSE) -> No | G1182: =VLOOKUP(A1182,table2!A1182:J3516,6,FALSE) -> No | H1182: =VLOOKUP(A1182,table2!A1182:J3516,7,FALSE) -> 0 | I1182: =VLOOKUP(A1182,table2!A1182:J3516,8,FALSE) -> No | J1182: =VLOOKUP(A1182,table2!A1182:J3516,9,FALSE) -> OBESITY | K1182: =VLOOKUP(A1182,table2!A1182:J3516,10,FALSE) -> DIABETES | L1182: =VLOOKUP(A1182,table3__3[],4,FALSE) -> 9749 | M1182: =VLOOKUP(A1182,table3__3[],5,FALSE) -> tier - 2 | N1182: =VLOOKUP(A1182,table3__3[],6,) -> tier - 1 | O1182: =VLOOKUP(A1182,table3__3[],7,FALSE) -> R1013 | P1182: =VLOOKUP(A1182,table3__3[],8,FALSE) -> 52 | Q1182: =VLOOKUP(A1181,table3__3[],8,) -> 52
... A2336: Id2335 | B2336: German | C2336: =VLOOKUP(A2336,table2!A2336:J4670,2,FALSE) -> 17.58 | D2336: =VLOOKUP(A2336,table2!A2336:J4670,3,FALSE) -> 4.51 | E2336: =VLOOKUP(A2336,table2!A2336:J4670,4,FALSE) -> No | F2336: =VLOOKUP(A2336,table2!A2336:J4670,5,FALSE) -> No | G2336: =VLOOKUP(A2336,table2!A2336:J4670,6,FALSE) -> No | H2336: =VLOOKUP(A2336,table2!A2336:J4670,7,FALSE) -> 1 | I2336: =VLOOKUP(A2336,table2!A2336:J4670,8,FALSE) -> No | J2336: =VLOOKUP(A2336,table2!A2336:J4670,9,FALSE) -> UNDER WEIGHT | K2336: =VLOOKUP(A2336,table2!A2336:J4670,10,FALSE) -> NORMAL | L2336: =VLOOKUP(A2336,table3__3[],4,FALSE) -> 51195 | M2336: =VLOOKUP(A2336,table3__3[],5,FALSE) -> tier - 1 | N2336: =VLOOKUP(A2336,table3__3[],6,) -> tier - 3 | O2336: =VLOOKUP(A2336,table3__3[],7,FALSE) -> R1011 | P2336: =VLOOKUP(A2336,table3__3[],8,FALSE) -> 28 | Q2336: =VLOOKUP(A2335,table3__3[],8,) -> 64

Sheet Sheet5
A3: Average of charges | B3: Column Labels | G3: Row Labels | H3: Average of HBA1C | I3: Sum of NumberOfMajorSurgeries | L3: Average of charges | M3: Column Labels | R3: Average of charges | S3: Column Labels
A4: Row Labels | B4: No | C4: Yes | D4: Grand Total | G4: No | H4: 6.6704427 | I4: 1417 | L4: Row Labels | M4: DIABETES | N4: NORMAL | O4: PREDIABETES | P4: Grand Total | R4: Row Labels | S4: tier - 1 | T4: tier - 2 | U4: tier - 3 | V4: Grand Total
A5: No | B5: 15928.625 | C5: 18156.248 | D5: 16298.89 | G5: Yes | H5: 5.1876389 | I5: 162 | L5: NORMAL WEIGHT | M5: 11507.145 | N5: 20703.175 | O5: 18777.494 | P5: 17396.835 | R5: R1011 | S5: 33016.822 | T5: 18997.274 | U5: 9250.3643 | V5: 19500.293
A6: Yes | B6: 2586.3614 | C6: 2978.3571 | D6: 2653.8361 | G6: Grand Total | H6: 6.5789979 | I6: 1579 | L6: OBESITY | M6: 7332.8405 | N6: 12422.481 | O6: 12090.433 | P6: 10553.67 | R6: R1012 | S6: 24775.306 | T6: 10312.035 | U6: 10179.983 | V6: 11831.823
A7: Grand Total | B7: 13155.85 | C7: 14895.524 | D7: 13447.161 | L7: OVER WEIGHT | M7: 9682.9032 | N7: 15346.648 | O7: 15915.21 | P7: 13674.501 | R7: R1013 | S7: 30888.254 | T7: 8293.807 | U7: 6857.1228 | V7: 10369.347
L8: UNDER WEIGHT | M8: 17919.879 | N8: 26976.085 | O8: 26330.893 | P8: 23477.364 | R8: R1014 | S8: 13891.7 | T8: 2395 | U8: 16950.5 | V8: 13477.923
L9: Grand Total | M9: 9386.7982 | N9: 15745.774 | O9: 15083.335 | P9: 13447.161 | R9: R1015 | S9: 21523.5 | T9: 16433.857 | U9: 7570.75 | V9: 14489.769
R10: R1016 | S10: 39868.625 | T10: 16075.917 | U10: 8132.9545 | V10: 13589.219
R11: R1017 | S11: 34070.571 | T11: 11365.625 | U11: 8667.4615 | V11: 14806.139
R12: R1018 | S12: 33476 | T12: 10139.667 | U12: 12571 | V12: 13272.889
R13: R1019 | S13: 27621.6 | T13: 8116.6364 | U13: 12706.8 | V13: 13633.038
R14: R1020 | T14: 6760.6667 | U14: 11716.333 | V14: 9238.5
R15: R1021 | T15: 7668.1489 | U15: 11518.696 | V15: 8933.3286
R16: R1022 | T16: 10102.222 | U16: 11637.8 | V16: 10650.643
R17: R1023 | S17: 18262 | T17: 13457.083 | U17: 12785.7 | V17: 13786.184
R18: R1024 | S18: 30744.615 | T18: 10189.367 | U18: 13360.917 | V18: 12603.253
R19: R1025 | T19: 6886.1053 | U19: 10510.381 | V19: 8788.85
R20: R1026 | S20: 18709.6 | T20: 11919.548 | U20: 12296.757 | V20: 12489.869
R21: unknown | S21: 20996.5 | V21: 20996.5
R22: Grand Total | S22: 29673.773 | T22: 11832.313 | U22: 9450.2781 | V22: 13447.161

Sheet Dashboard
F1: HEALTHCARE ANALYSIS DASHBOARD
V21: =SUM(Table1[charges]) -> 31399122

Sheet HEALTH CARE2
A1: customer id | B1: first name | C1: BMI | D1: HBA1C | E1: Heart Issues | F1: Any Transplants | G1: Cancer history | H1: NumberOfMajorSurgeries | I1: smoker | J1: diabetes status | K1: weight status | L1: charges | M1: Hospital tier | N1: City tier | O1: State ID | P1: Date of birth | Q1: AGE
A2: id1 | B2: =VLOOKUP(A2,cleaned_customer_names[],2,FALSE) -> Hawks | C2: =VLOOKUP(A2,cleaned_Medical_Examinations[],2,FALSE) -> 47.41 | D2: =VLOOKUP(A2,cleaned_Medical_Examinations[],3,FALSE) -> 7.47 | E2: =VLOOKUP(A2,cleaned_Medical_Examinations[],4,FALSE) -> No | F2: =VLOOKUP(A2,cleaned_Medical_Examinations[],5,FALSE) -> No | G2: =VLOOKUP(A2,cleaned_Medical_Examinations[],6,FALSE) -> No | H2: =VLOOKUP(A2,cleaned_Medical_Examinations[],7,FALSE) -> 0 | I2: =VLOOKUP(A2,cleaned_Medical_Examinations[],8,FALSE) -> Yes | J2: =VLOOKUP(A2,cleaned_Medical_Examinations[],9,FALSE) -> OBESITY | K2: =VLOOKUP(A2,cleaned_Medical_Examinations[],10,FALSE) -> DIABETES | L2: =VLOOKUP(A2,table3!A2:H2336,4,) -> 564 | M2: =VLOOKUP(A2,table3!A2:H2336,5,FALSE) -> tier - 2 | N2: =VLOOKUP(A2,table3!A2:H2336,6,FALSE) -> tier - 3 | O2: =VLOOKUP(A2,table3!A2:H2336,7,FALSE) -> R1013 | P2: =VLOOKUP(A2,table3!A2:H2336,2,FALSE) -> 33794 | Q2: =VLOOKUP(A2,table3!A2:H2336,8,FALSE) -> 30
A3: Id2 | B3: =VLOOKUP(A3,cleaned_customer_names[],2,FALSE) -> Lehner | C3: =VLOOKUP(A3,cleaned_Medical_Examinations[],2,FALSE) -> 30.36 | D3: =VLOOKUP(A3,cleaned_Medical_Examinations[],3,FALSE) -> 5.77 | E3: =VLOOKUP(A3,cleaned_Medical_Examinations[],4,FALSE) -> No | F3: =VLOOKUP(A3,cleaned_Medical_Examinations[],5,FALSE) -> No | G3: =VLOOKUP(A3,cleaned_Medical_Examinations[],6,FALSE) -> No | H3: =VLOOKUP(A3,cleaned_Medical_Examinations[],7,FALSE) -> 0 | I3: =VLOOKUP(A3,cleaned_Medical_Examinations[],8,FALSE) -> Yes | J3: =VLOOKUP(A3,cleaned_Medical_Examinations[],9,FALSE) -> OBESITY | K3: =VLOOKUP(A3,cleaned_Medical_Examinations[],10,FALSE) -> PREDIABETES | L3: =VLOOKUP(A3,table3!A3:H2337,4,) -> 571 | M3: =VLOOKUP(A3,table3!A3:H2337,5,FALSE) -> tier - 2 | N3: =VLOOKUP(A3,table3!A3:H2337,6,FALSE) -> tier - 1 | O3: =VLOOKUP(A3,table3!A3:H2337,7,FALSE) -> R1013 | P3: =VLOOKUP(A3,table3!A3:H2337,2,FALSE) -> 33938 | Q3: =VLOOKUP(A3,table3!A3:H2337,8,FALSE) -> 30
A4: Id3 | B4: =VLOOKUP(A4,cleaned_customer_names[],2,FALSE) -> Lu | C4: =VLOOKUP(A4,cleaned_Medical_Examinations[],2,FALSE) -> 34.485 | D4: =VLOOKUP(A4,cleaned_Medical_Examinations[],3,FALSE) -> 11.87 | E4: =VLOOKUP(A4,cleaned_Medical_Examinations[],4,FALSE) -> Yes | F4: =VLOOKUP(A4,cleaned_Medical_Examinations[],5,FALSE) -> No | G4: =VLOOKUP(A4,cleaned_Medical_Examinations[],6,FALSE) -> No | H4: =VLOOKUP(A4,cleaned_Medical_Examinations[],7,FALSE) -> 2 | I4: =VLOOKUP(A4,cleaned_Medical_Examinations[],8,FALSE) -> Yes | J4: =VLOOKUP(A4,cleaned_Medical_Examinations[],9,FALSE) -> OBESITY | K4: =VLOOKUP(A4,cleaned_Medical_Examinations[],10,FALSE) -> DIABETES | L4: =VLOOKUP(A4,table3!A4:H2338,4,) -> 600 | M4: =VLOOKUP(A4,table3!A4:H2338,5,FALSE) -> tier - 2 | N4: =VLOOKUP(A4,table3!A4:H2338,6,FALSE) -> tier - 1 | O4: =VLOOKUP(A4,table3!A4:H2338,7,FALSE) -> R1013 | P4: =VLOOKUP(A4,table3!A4:H2338,2,FALSE) -> 34150 | Q4: =VLOOKUP(A4,table3!A4:H2338,8,FALSE) -> 29
A5: Id4 | B5: =VLOOKUP(A5,cleaned_customer_names[],2,FALSE) -> Osborne | C5: =VLOOKUP(A5,cleaned_Medical_Examinations[],2,FALSE) -> 38.095 | D5: =VLOOKUP(A5,cleaned_Medical_Examinations[],3,FALSE) -> 6.05 | E5: =VLOOKUP(A5,cleaned_Medical_Examinations[],4,FALSE) -> No | F5: =VLOOKUP(A5,cleaned_Medical_Examinations[],5,FALSE) -> No | G5: =VLOOKUP(A5,cleaned_Medical_Examinations[],6,FALSE) -> No | H5: =VLOOKUP(A5,cleaned_Medical_Examinations[],7,FALSE) -> 0 | I5: =VLOOKUP(A5,cleaned_Medical_Examinations[],8,FALSE) -> Yes | J5: =VLOOKUP(A5,cleaned_Medical_Examinations[],9,FALSE) -> OBESITY | K5: =VLOOKUP(A5,cleaned_Medical_Examinations[],10,FALSE) -> PREDIABETES | L5: =VLOOKUP(A5,table3!A5:H2339,4,) -> 605 | M5: =VLOOKUP(A5,table3!A5:H2339,5,FALSE) -> tier - 3 | N5: =VLOOKUP(A5,table3!A5:H2339,6,FALSE) -> tier - 3 | O5: =VLOOKUP(A5,table3!A5:H2339,7,FALSE) -> R1013 | P5: =VLOOKUP(A5,table3!A5:H2339,2,FALSE) -> 33860 | Q5: =VLOOKUP(A5,table3!A5:H2339,8,FALSE) -> 30
A6: Id5 | B6: =VLOOKUP(A6,cleaned_customer_names[],2,FALSE) -> Kadala | C6: =VLOOKUP(A6,cleaned_Medical_Examinations[],2,FALSE) -> 35.53 | D6: =VLOOKUP(A6,cleaned_Medical_Examinations[],3,FALSE) -> 5.45 | E6: =VLOOKUP(A6,cleaned_Medical_Examinations[],4,FALSE) -> No | F6: =VLOOKUP(A6,cleaned_Medical_Examinations[],5,FALSE) -> No | G6: =VLOOKUP(A6,cleaned_Medical_Examinations[],6,FALSE) -> No | H6: =VLOOKUP(A6,cleaned_Medical_Examinations[],7,FALSE) -> 0 | I6: =VLOOKUP(A6,cleaned_Medical_Examinations[],8,FALSE) -> Yes | J6: =VLOOKUP(A6,cleaned_Medical_Examinations[],9,FALSE) -> OBESITY | K6: =VLOOKUP(A6,cleaned_Medical_Examinations[],10,FALSE) -> NORMAL | L6: =VLOOKUP(A6,table3!A6:H2340,4,) -> 637 | M6: =VLOOKUP(A6,table3!A6:H2340,5,FALSE) -> tier - 3 | N6: =VLOOKUP(A6,table3!A6:H2340,6,FALSE) -> tier - 3 | O6: =VLOOKUP(A6,table3!A6:H2340,7,FALSE) -> R1013 | P6: =VLOOKUP(A6,table3!A6:H2340,2,FALSE) -> 36003 | Q6: =VLOOKUP(A6,table3!A6:H2340,8,FALSE) -> 24
A7: Id6 | B7: =VLOOKUP(A7,cleaned_customer_names[],2,FALSE) -> Baker | C7: =VLOOKUP(A7,cleaned_Medical_Examinations[],2,FALSE) -> 32.8 | D7: =VLOOKUP(A7,cleaned_Medical_Examinations[],3,FALSE) -> 6.59 | E7: =VLOOKUP(A7,cleaned_Medical_Examinations[],4,FALSE) -> No | F7: =VLOOKUP(A7,cleaned_Medical_Examinations[],5,FALSE) -> No | G7: =VLOOKUP(A7,cleaned_Medical_Examinations[],6,FALSE) -> No | H7: =VLOOKUP(A7,cleaned_Medical_Examinations[],7,FALSE) -> 0 | I7: =VLOOKUP(A7,cleaned_Medical_Examinations[],8,FALSE) -> Yes | J7: =VLOOKUP(A7,cleaned_Medical_Examinations[],9,FALSE) -> OBESITY | K7: =VLOOKUP(A7,cleaned_Medical_Examinations[],10,FALSE) -> DIABETES | L7: =VLOOKUP(A7,table3!A7:H2341,4,) -> 646 | M7: =VLOOKUP(A7,table3!A7:H2341,5,FALSE) -> tier - 3 | N7: =VLOOKUP(A7,table3!A7:H2341,6,FALSE) -> tier - 3 | O7: =VLOOKUP(A7,table3!A7:H2341,7,FALSE) -> R1012 | P7: =VLOOKUP(A7,table3!A7:H2341,2,FALSE) -> 37215 | Q7: =VLOOKUP(A7,table3!A7:H2341,8,FALSE) -> 21
A8: Id7 | B8: =VLOOKUP(A8,cleaned_customer_names[],2,FALSE) -> Macpherson | C8: =VLOOKUP(A8,cleaned_Medical_Examinations[],2,FALSE) -> 36.4 | D8: =VLOOKUP(A8,cleaned_Medical_Examinations[],3,FALSE) -> 6.07 | E8: =VLOOKUP(A8,cleaned_Medical_Examinations[],4,FALSE) -> No | F8: =VLOOKUP(A8,cleaned_Medical_Examinations[],5,FALSE) -> No | G8: =VLOOKUP(A8,cleaned_Medical_Examinations[],6,FALSE) -> No | H8: =VLOOKUP(A8,cleaned_Medical_Examinations[],7,FALSE) -> 0 | I8: =VLOOKUP(A8,cleaned_Medical_Examinations[],8,FALSE) -> Yes | J8: =VLOOKUP(A8,cleaned_Medical_Examinations[],9,FALSE) -> OBESITY | K8: =VLOOKUP(A8,cleaned_Medical_Examinations[],10,FALSE) -> PREDIABETES | L8: =VLOOKUP(A8,table3!A8:H2342,4,) -> 650 | M8: =VLOOKUP(A8,table3!A8:H2342,5,FALSE) -> tier - 3 | N8: =VLOOKUP(A8,table3!A8:H2342,6,FALSE) -> tier - 3 | O8: =VLOOKUP(A8,table3!A8:H2342,7,FALSE) -> R1013 | P8: =VLOOKUP(A8,table3!A8:H2342,2,FALSE) -> 34121 | Q8: =VLOOKUP(A8,table3!A8:H2342,8,FALSE) -> 30
A9: Id8 | B9: =VLOOKUP(A9,cleaned_customer_names[],2,FALSE) -> Hallman | C9: =VLOOKUP(A9,cleaned_Medical_Examinations[],2,FALSE) -> 36.96 | D9: =VLOOKUP(A9,cleaned_Medical_Examinations[],3,FALSE) -> 7.93 | E9: =VLOOKUP(A9,cleaned_Medical_Examinations[],4,FALSE) -> No | F9: =VLOOKUP(A9,cleaned_Medical_Examinations[],5,FALSE) -> No | G9: =VLOOKUP(A9,cleaned_Medical_Examinations[],6,FALSE) -> No | H9: =VLOOKUP(A9,cleaned_Medical_Examinations[],7,FALSE) -> 3 | I9: =VLOOKUP(A9,cleaned_Medical_Examinations[],8,FALSE) -> Yes | J9: =VLOOKUP(A9,cleaned_Medical_Examinations[],9,FALSE) -> OBESITY | K9: =VLOOKUP(A9,cleaned_Medical_Examinations[],10,FALSE) -> DIABETES | L9: =VLOOKUP(A9,table3!A9:H2343,4,) -> 650 | M9: =VLOOKUP(A9,table3!A9:H2343,5,FALSE) -> tier - 3 | N9: =VLOOKUP(A9,table3!A9:H2343,6,FALSE) -> tier - 3 | O9: =VLOOKUP(A9,table3!A9:H2343,7,FALSE) -> R1013 | P9: =VLOOKUP(A9,table3!A9:H2343,2,FALSE) -> 34884 | Q9: =VLOOKUP(A9,table3!A9:H2343,8,FALSE) -> 27
A10: Id9 | B10: =VLOOKUP(A10,cleaned_customer_names[],2,FALSE) -> Moran | C10: =VLOOKUP(A10,cleaned_Medical_Examinations[],2,FALSE) -> 41.14 | D10: =VLOOKUP(A10,cleaned_Medical_Examinations[],3,FALSE) -> 9.58 | E10: =VLOOKUP(A10,cleaned_Medical_Examinations[],4,FALSE) -> Yes | F10: =VLOOKUP(A10,cleaned_Medical_Examinations[],5,FALSE) -> No | G10: =VLOOKUP(A10,cleaned_Medical_Examinations[],6,FALSE) -> Yes | H10: =VLOOKUP(A10,cleaned_Medical_Examinations[],7,FALSE) -> 1 | I10: =VLOOKUP(A10,cleaned_Medical_Examinations[],8,FALSE) -> Yes | J10: =VLOOKUP(A10,cleaned_Medical_Examinations[],9,FALSE) -> OBESITY | K10: =VLOOKUP(A10,cleaned_Medical_Examinations[],10,FALSE) -> DIABETES | L10: =VLOOKUP(A10,table3!A10:H2344,4,) -> 668 | M10: =VLOOKUP(A10,table3!A10:H2344,5,FALSE) -> tier - 3 | N10: =VLOOKUP(A10,table3!A10:H2344,6,FALSE) -> tier - 2 | O10: =VLOOKUP(A10,table3!A10:H2344,7,FALSE) -> R1012 | P10: =VLOOKUP(A10,table3!A10:H2344,2,FALSE) -> 37589 | Q10: =VLOOKUP(A10,table3!A10:H2344,8,FALSE) -> 20
A11: Id10 | B11: =VLOOKUP(A11,cleaned_customer_names[],2,FALSE) -> Benner | C11: =VLOOKUP(A11,cleaned_Medical_Examinations[],2,FALSE) -> 38.06 | D11: =VLOOKUP(A11,cleaned_Medical_Examinations[],3,FALSE) -> 10.79 | E11: =VLOOKUP(A11,cleaned_Medical_Examinations[],4,FALSE) -> No | F11: =VLOOKUP(A11,cleaned_Medical_Examinations[],5,FALSE) -> No | G11: =VLOOKUP(A11,cleaned_Medical_Examinations[],6,FALSE) -> No | H11: =VLOOKUP(A11,cleaned_Medical_Examinations[],7,FALSE) -> 0 | I11: =VLOOKUP(A11,cleaned_Medical_Examinations[],8,FALSE) -> Yes | J11: =VLOOKUP(A11,cleaned_Medical_Examinations[],9,FALSE) -> OBESITY | K11: =VLOOKUP(A11,cleaned_Medical_Examinations[],10,FALSE) -> DIABETES | L11: =VLOOKUP(A11,table3!A11:H2345,4,) -> 670 | M11: =VLOOKUP(A11,table3!A11:H2345,5,FALSE) -> tier - 3 | N11: =VLOOKUP(A11,table3!A11:H2345,6,FALSE) -> tier - 3 | O11: =VLOOKUP(A11,table3!A11:H2345,7,FALSE) -> R1013 | P11: =VLOOKUP(A11,table3!A11:H2345,2,FALSE) -> 35743 | Q11: =VLOOKUP(A11,table3!A11:H2345,8,FALSE) -> 25
A12: Id11 | B12: =VLOOKUP(A12,cleaned_customer_names[],2,FALSE) -> Fierro Vargas | C12: =VLOOKUP(A12,cleaned_Medical_Examinations[],2,FALSE) -> 37.7 | D12: =VLOOKUP(A12,cleaned_Medical_Examinations[],3,FALSE) -> 5.96 | E12: =VLOOKUP(A12,cleaned_Medical_Examinations[],4,FALSE) -> Yes | F12: =VLOOKUP(A12,cleaned_Medical_Examinations[],5,FALSE) -> No | G12: =VLOOKUP(A12,cleaned_Medical_Examinations[],6,FALSE) -> No | H12: =VLOOKUP(A12,cleaned_Medical_Examinations[],7,FALSE) -> 2 | I12: =VLOOKUP(A12,cleaned_Medical_Examinations[],8,FALSE) -> Yes | J12: =VLOOKUP(A12,cleaned_Medical_Examinations[],9,FALSE) -> OBESITY | K12: =VLOOKUP(A12,cleaned_Medical_Examinations[],10,FALSE) -> PREDIABETES | L12: =VLOOKUP(A12,table3!A12:H2346,4,) -> 688 | M12: =VLOOKUP(A12,table3!A12:H2346,5,FALSE) -> tier - 3 | N12: =VLOOKUP(A12,table3!A12:H2346,6,FALSE) -> tier - 2 | O12: =VLOOKUP(A12,table3!A12:H2346,7,FALSE) -> R1013 | P12: =VLOOKUP(A12,table3!A12:H2346,2,FALSE) -> 37146 | Q12: =VLOOKUP(A12,table3!A12:H2346,8,FALSE) -> 21
A13: Id12 | B13: =VLOOKUP(A13,cleaned_customer_names[],2,FALSE) -> Franz | C13: =VLOOKUP(A13,cleaned_Medical_Examinations[],2,FALSE) -> 42.13 | D13: =VLOOKUP(A13,cleaned_Medical_Examinations[],3,FALSE) -> 11.9 | E13: =VLOOKUP(A13,cleaned_Medical_Examinations[],4,FALSE) -> No | F13: =VLOOKUP(A13,cleaned_Medical_Examinations[],5,FALSE) -> No | G13: =VLOOKUP(A13,cleaned_Medical_Examinations[],6,FALSE) -> No | H13: =VLOOKUP(A13,cleaned_Medical_Examinations[],7,FALSE) -> 0 | I13: =VLOOKUP(A13,cleaned_Medical_Examinations[],8,FALSE) -> Yes | J13: =VLOOKUP(A13,cleaned_Medical_Examinations[],9,FALSE) -> OBESITY | K13: =VLOOKUP(A13,cleaned_Medical_Examinations[],10,FALSE) -> DIABETES | L13: =VLOOKUP(A13,table3!A13:H2347,4,) -> 700 | M13: =VLOOKUP(A13,table3!A13:H2347,5,FALSE) -> tier - 2 | N13: =VLOOKUP(A13,table3!A13:H2347,6,FALSE) -> tier - 3 | O13: =VLOOKUP(A13,table3!A13:H2347,7,FALSE) -> R1013 | P13: =VLOOKUP(A13,table3!A13:H2347,2,FALSE) -> 36520 | Q13: =VLOOKUP(A13,table3!A13:H2347,8,FALSE) -> 23
... A2336: Id2335 | B2336: =VLOOKUP(A2336,cleaned_customer_names[],2,FALSE) -> German | C2336: =VLOOKUP(A2336,cleaned_Medical_Examinations[],2,FALSE) -> 17.58 | D2336: =VLOOKUP(A2336,cleaned_Medical_Examinations[],3,FALSE) -> 4.51 | E2336: =VLOOKUP(A2336,cleaned_Medical_Examinations[],4,FALSE) -> No | F2336: =VLOOKUP(A2336,cleaned_Medical_Examinations[],5,FALSE) -> No | G2336: =VLOOKUP(A2336,cleaned_Medical_Examinations[],6,FALSE) -> No | H2336: =VLOOKUP(A2336,cleaned_Medical_Examinations[],7,FALSE) -> 1 | I2336: =VLOOKUP(A2336,cleaned_Medical_Examinations[],8,FALSE) -> No | J2336: =VLOOKUP(A2336,cleaned_Medical_Examinations[],9,FALSE) -> UNDER WEIGHT | K2336: =VLOOKUP(A2336,cleaned_Medical_Examinations[],10,FALSE) -> NORMAL | L2336: =VLOOKUP(A2336,table3!A2336:H4670,4,) -> 51195 | M2336: =VLOOKUP(A2336,table3!A2336:H4670,5,FALSE) -> tier - 1 | N2336: =VLOOKUP(A2336,table3!A2336:H4670,6,FALSE) -> tier - 3 | O2336: =VLOOKUP(A2336,table3!A2336:H4670,7,FALSE) -> R1011 | P2336: =VLOOKUP(A2336,table3!A2336:H4670,2,FALSE) -> 34634 | Q2336: =VLOOKUP(A2336,table3!A2336:H4670,8,FALSE) -> 28

Sheet table2
A1: Customer ID | B1: BMI | C1: HBA1C | D1: Heart Issues | E1: Any Transplants | F1: Cancer history | G1: NumberOfMajorSurgeries | H1: smoker | I1: diabetes status | J1: weight status
A2: Id1 | B2: 47.41 | C2: 7.47 | D2: No | E2: No | F2: No | G2: 0 | H2: Yes | I2: OBESITY | J2: DIABETES
A3: Id2 | B3: 30.36 | C3: 5.77 | D3: No | E3: No | F3: No | G3: 0 | H3: Yes | I3: OBESITY | J3: PREDIABETES
A4: Id3 | B4: 34.485 | C4: 11.87 | D4: Yes | E4: No | F4: No | G4: 2 | H4: Yes | I4: OBESITY | J4: DIABETES
A5: Id4 | B5: 38.095 | C5: 6.05 | D5: No | E5: No | F5: No | G5: 0 | H5: Yes | I5: OBESITY | J5: PREDIABETES
A6: Id5 | B6: 35.53 | C6: 5.45 | D6: No | E6: No | F6: No | G6: 0 | H6: Yes | I6: OBESITY | J6: NORMAL
A7: Id6 | B7: 32.8 | C7: 6.59 | D7: No | E7: No | F7: No | G7: 0 | H7: Yes | I7: OBESITY | J7: DIABETES
A8: Id7 | B8: 36.4 | C8: 6.07 | D8: No | E8: No | F8: No | G8: 0 | H8: Yes | I8: OBESITY | J8: PREDIABETES
A9: Id8 | B9: 36.96 | C9: 7.93 | D9: No | E9: No | F9: No | G9: 3 | H9: Yes | I9: OBESITY | J9: DIABETES
A10: Id9 | B10: 41.14 | C10: 9.58 | D10: Yes | E10: No | F10: Yes | G10: 1 | H10: Yes | I10: OBESITY | J10: DIABETES
A11: Id10 | B11: 38.06 | C11: 10.79 | D11: No | E11: No | F11: No | G11: 0 | H11: Yes | I11: OBESITY | J11: DIABETES
A12: Id11 | B12: 37.7 | C12: 5.96 | D12: Yes | E12: No | F12: No | G12: 2 | H12: Yes | I12: OBESITY | J12: PREDIABETES
A13: Id12 | B13: 42.13 | C13: 11.9 | D13: No | E13: No | F13: No | G13: 0 | H13: Yes | I13: OBESITY | J13: DIABETES
... A2336: Id2335 | B2336: 17.58 | C2336: 4.51 | D2336: No | E2336: No | F2336: No | G2336: 1 | H2336: No | I2336: UNDER WEIGHT | J2336: NORMAL

Sheet table1
A1: Customer ID | B1: First name | C1: Title | D1: Last name
A2: Id1 | B2: Hawks | C2: Ms | D2: Kelly
A3: Id2 | B3: Lehner | C3: Mr | D3: Matthew D
A4: Id3 | B4: Lu | C4: Mr | D4: Phil
A5: Id4 | B5: Osborne | C5: Ms | D5: Kelsey
A6: Id5 | B6: Kadala | C6: Ms | D6: Kristyn
A7: Id6 | B7: Baker | C7: Mr | D7: Russell B
A8: Id7 | B8: Macpherson | C8: Mr | D8: Scott
A9: Id8 | B9: Hallman | C9: Mr | D9: Stephen
A10: Id9 | B10: Moran | C10: Mr | D10: Patrick R
A11: Id10 | B11: Benner | C11: Ms | D11: Brooke N
A12: Id11 | B12: Fierro Vargas | C12: Ms | D12: Paola Andrea
... A2336: Id2335 | B2336: German | C2336: Mr | D2336: Aaron K

Sheet table3
A1: Customer ID | B1: date of birth | C1: children | D1: charges | E1: Hospital tier | F1: City tier | G1: State ID | H1: age
A2: id1 | B2: 33794 | C2: 0 | D2: 564 | E2: tier - 2 | F2: tier - 3 | G2: R1013 | H2: 30
A3: Id2 | B3: 33938 | C3: 0 | D3: 571 | E3: tier - 2 | F3: tier - 1 | G3: R1013 | H3: 30
A4: Id3 | B4: 34150 | C4: 0 | D4: 600 | E4: tier - 2 | F4: tier - 1 | G4: R1013 | H4: 29
A5: Id4 | B5: 33860 | C5: 0 | D5: 605 | E5: tier - 3 | F5: tier - 3 | G5: R1013 | H5: 30
A6: Id5 | B6: 36003 | C6: 0 | D6: 637 | E6: tier - 3 | F6: tier - 3 | G6: R1013 | H6: 24
A7: Id6 | B7: 37215 | C7: 0 | D7: 646 | E7: tier - 3 | F7: tier - 3 | G7: R1012 | H7: 21
A8: Id7 | B8: 34121 | C8: 0 | D8: 650 | E8: tier - 3 | F8: tier - 3 | G8: R1013 | H8: 30
A9: Id8 | B9: 34884 | C9: 0 | D9: 650 | E9: tier - 3 | F9: tier - 3 | G9: R1013 | H9: 27
A10: Id9 | B10: 37589 | C10: 0 | D10: 668 | E10: tier - 3 | F10: tier - 2 | G10: R1012 | H10: 20
A11: Id10 | B11: 35743 | C11: 0 | D11: 670 | E11: tier - 3 | F11: tier - 3 | G11: R1013 | H11: 25
A12: Id11 | B12: 37146 | C12: 0 | D12: 688 | E12: tier - 3 | F12: tier - 2 | G12: R1013 | H12: 21
A13: Id12 | B13: 36520 | C13: 0 | D13: 700 | E13: tier - 2 | F13: tier - 3 | G13: R1013 | H13: 23
... A2342: Id1 | B2342: 25123 | C2342: 0 | D2342: 63770 | E2342: tier - 1 | F2342: tier - 3 | G2342: R1013 | H2342: 54

Sheet Hospitalisation Details
A1: Customer ID | B1: year | C1: month | D1: date | E1: children | F1: charges | G1: Hospital tier | H1: City tier | I1: State ID
A2: Id2335 | B2: 1992 | C2: Jul | D2: 9 | E2: 0 | F2: 563.84 | G2: tier - 2 | H2: tier - 3 | I2: R1013
A3: Id2334 | B3: 1992 | C3: Nov | D3: 30 | E3: 0 | F3: 570.62 | G3: tier - 2 | H3: tier - 1 | I3: R1013
A4: Id2333 | B4: 1993 | C4: Jun | D4: 30 | E4: 0 | F4: 600 | G4: tier - 2 | H4: tier - 1 | I4: R1013
A5: Id2332 | B5: 1992 | C5: Sep | D5: 13 | E5: 0 | F5: 604.54 | G5: tier - 3 | H5: tier - 3 | I5: R1013
A6: Id2331 | B6: 1998 | C6: Jul | D6: 27 | E6: 0 | F6: 637.26 | G6: tier - 3 | H6: tier - 3 | I6: R1013
A7: Id2330 | B7: 2001 | C7: Nov | D7: 20 | E7: 0 | F7: 646.14 | G7: tier - 3 | H7: tier - 3 | I7: R1012
A8: Id2329 | B8: 1993 | C8: Jun | D8: 1 | E8: 0 | F8: 650 | G8: tier - 3 | H8: tier - 3 | I8: R1013
A9: Id2328 | B9: 1995 | C9: Jul | D9: 4 | E9: 0 | F9: 650 | G9: tier - 3 | H9: tier - 3 | I9: R1013
A10: Id2327 | B10: 2002 | C10: Nov | D10: 29 | E10: 0 | F10: 668 | G10: tier - 3 | H10: tier - 2 | I10: R1012
A11: Id2326 | B11: 1997 | C11: Nov | D11: 9 | E11: 0 | F11: 670 | G11: tier - 3 | H11: tier - 3 | I11: R1013
A12: Id2325 | B12: 2001 | C12: Sep | D12: 12 | E12: 0 | F12: 687.54 | G12: tier - 3 | H12: tier - 2 | I12: R1013
A13: Id2324 | B13: 1999 | C13: Dec | D13: 26 | E13: 0 | F13: 700 | G13: ? | H13: tier - 3 | I13: R1013
... A1050: Id1290 | B1050: 1977 | C1050: Jul | D1050: 26 | E1050: 2 | F1050: 8527.53 | G1050: tier - 2 | H1050: tier - 2 | I1050: R1013
A1051: Id1289 | B1051: ? | C1051: Jul | D1051: 24 | E1051: 0 | F1051: 8534.67 | G1051: tier - 2 | H1051: tier - 3 | I1051: R1024
A1052: Id1288 | B1052: 1981 | C1052: Dec | D1052: 27 | E1052: 3 | F1052: 8538.29 | G1052: tier - 2 | H1052: tier - 3 | I1052: R1024
A1053: Id1287 | B1053: 1975 | C1053: Nov | D1053: 6 | E1053: 1 | F1053: 8539.67 | G1053: tier - 2 | H1053: tier - 3 | I1053: R1011
A1054: Id1286 | B1054: ? | C1054: Dec | D1054: 12 | E1054: 1 | F1054: 8547.69 | G1054: tier - 2 | H1054: tier - 1 | I1054: R1013
A1055: Id1285 | B1055: 1975 | C1055: Aug | D1055: 6 | E1055: 1 | F1055: 8551.35 | G1055: tier - 2 | H1055: tier - 2 | I1055: R1011
A1056: Id1284 | B1056: 1975 | C1056: Aug | D1056: 21 | E1056: 1 | F1056: 8556.91 | G1056: tier - 2 | H1056: tier - 1 | I1056: R1011
A1057: Id1283 | B1057: 1988 | C1057: Sep | D1057: 21 | E1057: 3 | F1057: 8567.25 | G1057: tier - 2 | H1057: tier - 1 | I1057: R1012
A1058: Id1282 | B1058: 1975 | C1058: Sep | D1058: 26 | E1058: 1 | F1058: 8569.86 | G1058: tier - 2 | H1058: tier - 3 | I1058: R1013
A1059: Id1281 | B1059: 1982 | C1059: Dec | D1059: 6 | E1059: 3 | F1059: 8572.04 | G1059: tier - 2 | H1059: tier - 2 | I1059: R1021
A1060: Id1280 | B1060: 1987 | C1060: Nov | D1060: 11 | E1060: 3 | F1060: 8573.3 | G1060: tier - 2 | H1060: tier - 2 | I1060: R1021
A1061: Id1279 | B1061: 1983 | C1061: Dec | D1061: 30 | E1061: 5 | F1061: 8582.3 | G1061: tier - 2 | H1061: tier - 1 | I1061: R1013
A1062: Id1278 | B1062: 1983 | C1062: Jul | D1062: 25 | E1062: 5 | F1062: 8596.83 | G1062: tier - 2 | H1062: tier - 3 | I1062: R1013
A1063: Id1277 | B1063: 1973 | C1063: Jul | D1063: 11 | E1063: 0 | F1063: 8601.33 | G1063: tier - 2 | H1063: tier - 1 | I1063: R1013
A1064: Id1276 | B1064: 1977 | C1064: Sep | D1064: 24 | E1064: 2 | F1064: 8603.82 | G1064: tier - 2 | H1064: tier - 1 | I1064: R1019
A1065: Id1275 | B1065: 1977 | C1065: Nov | D1065: 12 | E1065: 2 | F1065: 8604.48 | G1065: tier - 3 | H1065: tier - 2 | I1065: R1016
A1066: Id1274 | B1066: 1977 | C1066: Oct | D1066: 15 | E1066: 3 | F1066: 8605.36 | G1066: tier - 2 | H1066: tier - 2 | I1066: R1013
... A2344: Id1 | B2344: 1968 | C2344: Oct | D2344: 12 | E2344: 0 | F2344: 63770.43 | G2344: tier - 1 | H2344: tier - 3 | I2344: R1013
